Workbook

Sheet Інструкція
B2: Greensource SGM 110 MWp · Ресурсний план випробувань паль · Фаза 2 (50 точок)
B3: Шаблон для заповнення · валюта € · масштабування від Фази 1 (5 точок) · ред. 1.0
B5: Мета | C5: Спланувати всі ресурси Фази 2 — польові випробування 50 точок (виривання + стиск), переважно геошурупи з попереднім бурінням (предрил). Шаблон для поетапного дозаповнення: змінюєте вхідні дані на листі «Параметри» — кількості й підсумки перераховуються самі.
B6: Уроки Фази 1 (враховано)
B7: Продуктивність | C7: Монтаж — 5 точок за 2 дні = 2,5 точки/день/бригада. Тестування — 5 точок за 5 днів одним експертом = 1 точка/день/бригада. Саме тестування — вузьке місце для 50 точок.
B8: Обладнання | C8: ГАЙК (гайковерт/копер для вкручення й забиття), предрил-установка (буріння під геошурупи), квадроцикл (переміщення полем), окремі комплекти для «виривання» і «стиск», генератор, повірка приладів.
B9: Що легко забути | C9: Реакційні анкери для pull-out, мобілізація/демобілізація, витратники предрилу, ГСМ, повне відрядження бригад, польові умови (жара/дощ/вода), резерв на непередбачене.
B10: Структура файлу
B11: 1. Параметри | C11: Вхідні дані + калькулятор: скільки тест-бригад і яка тривалість. Тут і тільки тут міняєте цифри.
B12: 2. Ресурсний план | C12: 7 розділів (персонал, обладнання, матеріали, логістика/відрядження, польові умови, документи/ТБ, резерв). Кількості — формули від «Параметрів»; ставки € — заповнюєте ви; вартість рахується сама.
B13: 3. Довідники | C13: Списки для випадаючих меню (тип статті, одиниці, категорія).
B14: Відрядження | C14: Блок «Логістика та відрядження» вести за внутрішнім положенням про відрядження; закриття — через авансовий звіт (див. каталог процедур).
B15: Як заповнювати
B16: Сині комірки | C16: Синій текст + жовте тло = ваш ввід (ставки €, окремі кількості). Чорні — формули, не чіпати.
B17: Розрахунок бригад | C17: Лист «Параметри», блок 5: таблиця 1–4 тест-бригади → тривалість. Рядок 3 бригади підсвічено як орієнтир.
B19: Легенда
C20: Поле для заповнення (ваш ввід)
C21: Формула / авто-розрахунок
C22: Заголовок / підсумок

Sheet Параметри
B1: Параметри та калькулятор Фази 2
B4: 1. ОБСЯГ РОБІТ ТА БАЗОВІ ДОПУЩЕННЯ
B5: Всього точок (Фаза 2) | C5: 50 | D5: точок
B6: — з них геошурупи (з предрилом) | C6: 45 | D6: точок | E6: переважно шурупи
B7: — з них забивні палі | C7: 5 | D7: точок
B8: Випробування «виривання» (pull-out) | C8: Так | E8: осьове розтягнення
B9: Випробування «стиск» (compression) | C9: Так | E9: осьове вдавлювання
B10: Реакційних анкерів на точку | C10: 2 | D10: шт | E10: для pull-out; скоригуйте
B11: Резерв на непередбачене | C11: 0.12 | D11: % | E11: частка від суми
B12: 2. ПРОДУКТИВНІСТЬ (ФАКТ ФАЗИ 1)
B13: Монтаж: точок/день/бригада | C13: 2.5 | D13: точ/дн | E13: Фаза 1: 5 точок за 2 дні
B14: Тестування: точок/день/бригада | C14: 1 | D14: точ/дн | E14: Фаза 1: 5 точок за 5 днів, 1 експерт
B15: Робочих днів на тиждень | C15: 6 | D15: дн
B17: 3. БРИГАДИ ТА СКЛАД (РІШЕННЯ)
B18: Монтажних бригад | C18: 2 | D18: бригад
B19: Тестових бригад | C19: 3 | D19: бригад | E19: орієнтир — мінімум 3
B20: Розмір монтажної бригади | C20: 4 | D20: осіб
B21: Розмір тестової бригади | C21: 2 | D21: осіб | E21: експерт + технік
B23: 4. РОЗРАХУНОК (АВТО — не редагувати)
B24: Монтаж — бригадо-днів (всього) | C24: =ROUNDUP((C6+C7)/C13,0) -> 20 | D24: бр-дн
B25: Тестування — бригадо-днів (всього) | C25: =ROUNDUP(C5/C14,0) -> 50 | D25: бр-дн | E25: вузьке місце
B26: Монтаж — календарних днів | C26: =ROUNDUP((C6+C7)/(C13*C18),0) -> 10 | D26: дн
B27: Тестування — календарних днів | C27: =ROUNDUP(C5/(C14*C19),0) -> 17 | D27: дн
B28: Польова тривалість (з нахлестом) + буфер | C28: =MAX(C26,C27)+2 -> 19 | D28: дн | E28: планова
B29: Польова тривалість (послідовно) | C29: =C26+C27 -> 27 | D29: дн | E29: консервативно
B30: Осіб у полі (всього) | C30: =C18*C20+C19*C21 -> 14 | D30: осіб
B32: 5. СКІЛЬКИ ПОТРІБНО ТЕСТ-БРИГАД? (тестування — вузьке місце)
B33: Тест-бригад | C33: Календарних днів | D33: Робочих тижнів
B34: 1 | C34: =ROUNDUP($C$5/($C$14*B34),0) -> 50 | D34: =ROUND(C34/$C$15,1) -> 8.3 | E34: Орієнтир — 3 тест-бригади (~17 роб. днів ≈ 3 тижні). Регулюйте кількістю бригад у блоці 3.
B35: 2 | C35: =ROUNDUP($C$5/($C$14*B35),0) -> 25 | D35: =ROUND(C35/$C$15,1) -> 4.2
B36: 3 | C36: =ROUNDUP($C$5/($C$14*B36),0) -> 17 | D36: =ROUND(C36/$C$15,1) -> 2.8
B37: 4 | C37: =ROUNDUP($C$5/($C$14*B37),0) -> 13 | D37: =ROUND(C37/$C$15,1) -> 2.2

Sheet Ресурсний план
A1: Ресурсний план — Greensource SGM 110 MWp · Фаза 2 · випробування 50 точок
A2: № | B2: Категорія RBS | C2: Ресурс / стаття витрат | D2: Тип | E2: Одиниця | F2: Кількість | G2: Ставка, € | H2: Вартість, € | I2: Постачальник | J2: Джерело к-сті / примітка
A3: 1 Персонал
A4: 1 | B4: 1 Персонал | C4: Геотехнічний експерт (випробування) | D4: Послуга | E4: люд-день | F4: =Параметри!$C$25 -> 50 | H4: =F4*G4 -> 0 | J4: 1 експерт/бригаду × бригадо-дні тесту
A5: 2 | B5: 1 Персонал | C5: Оператор ГАЙКа (вкручення/забиття) | D5: ЗП / бригада | E5: люд-день | F5: =Параметри!$C$24 -> 20 | H5: =F5*G5 -> 0 | J5: бригадо-дні монтажу
A6: 3 | B6: 1 Персонал | C6: Оператор предрил-установки | D6: ЗП / бригада | E6: люд-день | F6: =ROUNDUP(Параметри!$C$24*Параметри!$C$6/(Параметри!$C$6+Параметри!$C$7),0) -> 18 | H6: =F6*G6 -> 0 | J6: частка геошурупів
A7: 4 | B7: 1 Персонал | C7: Помічники монтажу | D7: ЗП / бригада | E7: люд-день | F7: =Параметри!$C$24*2 -> 40 | H7: =F7*G7 -> 0 | J7: ≈2 на бригаду
A8: 5 | B8: 1 Персонал | C8: Технік/помічник випробувань | D8: ЗП / бригада | E8: люд-день | F8: =Параметри!$C$25 -> 50 | H8: =F8*G8 -> 0 | J8: 1 на тест-бригаду
A9: 6 | B9: 1 Персонал | C9: Супервайзер робіт | D9: ЗП / бригада | E9: люд-день | F9: =Параметри!$C$28 -> 19 | H9: =F9*G9 -> 0 | J9: вся польова тривалість
A10: 7 | B10: 1 Персонал | C10: Геодезист (розмітка 50 точок) | D10: Послуга | E10: люд-день | F10: =ROUNDUP(Параметри!$C$5/25,0) -> 2 | H10: =F10*G10 -> 0 | J10: ≈25 точок/день
C11: Разом: 1 Персонал | H11: =SUM(H4:H10) -> 0
A12: 2 Обладнання
A13: 8 | B13: 2 Обладнання | C13: ГАЙК — гайковерт/копер | D13: Оренда | E13: бригадо-день | F13: =Параметри!$C$24 -> 20 | H13: =F13*G13 -> 0 | J13: вкручення + забиття
A14: 9 | B14: 2 Обладнання | C14: Предрил-установка (буріння) | D14: Оренда | E14: бригадо-день | F14: =ROUNDUP(Параметри!$C$24*Параметри!$C$6/(Параметри!$C$6+Параметри!$C$7),0) -> 18 | H14: =F14*G14 -> 0 | J14: тільки геошурупи
A15: 10 | B15: 2 Обладнання | C15: Квадроцикл (переміщення полем) | D15: Оренда | E15: бригадо-день | F15: =Параметри!$C$24+Параметри!$C$25 -> 70 | H15: =F15*G15 -> 0 | J15: монтаж + тест
A16: 11 | B16: 2 Обладнання | C16: Комплект «виривання»: домкрат, насос, реакц. балка, динамометр, індикатори | D16: Оренда | E16: бригадо-день | F16: =Параметри!$C$25 -> 50 | H16: =F16*G16 -> 0 | J16: pull-out
A17: 12 | B17: 2 Обладнання | C17: Комплект «стиск»: домкрат, реакц. система, прогиноміри | D17: Оренда | E17: бригадо-день | F17: =Параметри!$C$25 -> 50 | H17: =F17*G17 -> 0 | J17: compression
A18: 13 | B18: 2 Обладнання | C18: Генератор | D18: Оренда | E18: бригадо-день | F18: =Параметри!$C$24+Параметри!$C$25 -> 70 | H18: =F18*G18 -> 0 | J18: живлення насосів/приладів
A19: 14 | B19: 2 Обладнання | C19: Повірка/калібрування приладів | D19: Послуга | E19: к-т | F19: =Параметри!$C$19 -> 3 | H19: =F19*G19 -> 0 | J19: перед стартом, на тест-бригаду
C20: Разом: 2 Обладнання | H20: =SUM(H13:H19) -> 0
A21: 3 Матеріали
A22: 15 | B22: 3 Матеріали | C22: Геошурупи тестові | D22: Купівля | E22: шт | F22: =Параметри!$C$6 -> 45 | H22: =F22*G22 -> 0 | J22: за к-стю геошурупів
A23: 16 | B23: 3 Матеріали | C23: Забивні палі тестові | D23: Купівля | E23: шт | F23: =Параметри!$C$7 -> 5 | H23: =F23*G23 -> 0 | J23: за к-стю забивних
A24: 17 | B24: 3 Матеріали | C24: Реакційні анкери/палі (pull-out) | D24: Купівля | E24: шт | F24: =Параметри!$C$5*Параметри!$C$10 -> 100 | H24: =F24*G24 -> 0 | J24: ≈2 на точку
A25: 18 | B25: 3 Матеріали | C25: Витратники предрилу (коронки/свердла) | D25: Купівля | E25: компл | F25: =Параметри!$C$6 -> 45 | H25: =F25*G25 -> 0 | J25: за к-стю геошурупів
A26: 19 | B26: 3 Матеріали | C26: ГСМ (дизель / бензин A-95) | D26: Купівля | E26: л | H26: =F26*G26 -> 0 | J26: ≈ бригадо-дні × добова витрата
A27: 20 | B27: 3 Матеріали | C27: Метизи / дрібні розхідники | D27: Купівля | E27: компл | H27: =F27*G27 -> 0 | J27: дозаповнити
C28: Разом: 3 Матеріали | H28: =SUM(H22:H27) -> 0
A29: 4 Логістика/відрядж.
A30: 21 | B30: 4 Логістика/відрядж. | C30: Мобілізація/демобілізація обладнання | D30: Послуга | E30: рейс | F30: =2 -> 2 | H30: =F30*G30 -> 0 | J30: туди-назад
A31: 22 | B31: 4 Логістика/відрядж. | C31: Проїзд бригад (до об'єкта і назад) | D31: Відрядження | E31: осіб | F31: =Параметри!$C$30 -> 14 | H31: =F31*G31 -> 0 | J31: за положенням про відрядження
A32: 23 | B32: 4 Логістика/відрядж. | C32: Проживання (готель) | D32: Відрядження | E32: людино-ніч | F32: =Параметри!$C$30*Параметри!$C$28 -> 266 | H32: =F32*G32 -> 0 | J32: осіб × польові дні
A33: 24 | B33: 4 Логістика/відрядж. | C33: Добові | D33: Відрядження | E33: люд-день | F33: =Параметри!$C$30*Параметри!$C$28 -> 266 | H33: =F33*G33 -> 0 | J33: за положенням; авансовий звіт
A34: 25 | B34: 4 Логістика/відрядж. | C34: Місцевий трансфер (готель↔майданчик) | D34: Відрядження | E34: люд-день | F34: =Параметри!$C$30*Параметри!$C$28 -> 266 | H34: =F34*G34 -> 0 | J34: щоденно
A35: 26 | B35: 4 Логістика/відрядж. | C35: Оренда/паливо авто для переміщень | D35: Змішано | E35: л | H35: =F35*G35 -> 0 | J35: дозаповнити
C36: Разом: 4 Логістика/відрядж. | H36: =SUM(H30:H35) -> 0
A37: 5 Польові умови
A38: 27 | B38: 5 Польові умови | C38: Намет/навіс/побутівка на майданчику | D38: Оренда | E38: компл | F38: =Параметри!$C$18+Параметри!$C$19 -> 5 | H38: =F38*G38 -> 0 | J38: 1 на бригаду; тінь/дощ
A39: 28 | B39: 5 Польові умови | C39: Питна вода та електроліти (жара) | D39: Купівля | E39: люд-день | F39: =Параметри!$C$30*Параметри!$C$28 -> 266 | H39: =F39*G39 -> 0 | J39: осіб × польові дні
A40: 29 | B40: 5 Польові умови | C40: Дощовики, непромокальний одяг, гумове взуття | D40: Купівля | E40: компл | F40: =Параметри!$C$30 -> 14 | H40: =F40*G40 -> 0 | J40: на особу
...

Sheet Довідники
A1: Тип статті | B1: Одиниця | C1: Категорія RBS
A2: Оренда | B2: люд-день | C2: 1 Персонал
A3: Купівля | B3: бригадо-день | C3: 2 Обладнання
A4: Послуга | B4: шт | C4: 3 Матеріали
A5: ЗП / бригада | B5: компл | C5: 4 Логістика/відрядж.
A6: Відрядження | B6: л | C6: 5 Польові умови
A7: Змішано | B7: людино-ніч | C7: 6 Документи/ТБ
B8: рейс | C8: 7 Резерв
B9: к-т
B10: поліс
B11: міс
B12: —
