Workbook

Sheet Параметри
B1: Параметри · калькулятор · прогноз бюджету
B2: Міняєте сині значення — кількості в реєстрі RBS і весь бюджет перераховуються самі. «Граєтеся» сценаріями.
B4: 1. ОБСЯГ ТА ДОПУЩЕННЯ
B5: Всього точок (Фаза 2) | C5: 50 | D5: точок | E5: драйвер масштабу
B6: Тип паль | C6: Геошурупи з предрилом | E6: усі точки — шурупи
B7: Реакційних анкерів на точку | C7: 2 | D7: шт | E7: для pull-out; скоригуйте
B8: ГСМ, л на бригадо-день | C8: 20 | D8: л/дн | E8: орієнтовна витрата
B9: Резерв на непередбачене | C9: 0.12 | D9: % | E9: частка від прямих витрат
B11: 2. ПРОДУКТИВНІСТЬ (ФАКТ ФАЗИ 1)
B12: Монтаж: точок/день/бригада | C12: 2.5 | D12: точ/дн | E12: Фаза 1: 5 точок за 2 дні
B13: Тестування: точок/день/бригада | C13: 1 | D13: точ/дн | E13: Фаза 1: 5 точок за 5 днів (1 експерт)
B14: Робочих днів на тиждень | C14: 6 | D14: дн
B16: 3. БРИГАДИ ТА СКЛАД (РІШЕННЯ)
B17: Монтажних бригад | C17: 2 | D17: бригад
B18: Тестових бригад | C18: 3 | D18: бригад | E18: орієнтир — мінімум 3
B19: Розмір монтажної бригади | C19: 4 | D19: осіб
B20: Розмір тестової бригади | C20: 2 | D20: осіб | E20: експерт + технік
B22: 4. РОЗРАХУНОК (АВТО — не редагувати)
B23: Монтаж — бригадо-днів (всього) | C23: =ROUNDUP(C5/C12,0) -> 20 | D23: бр-дн
B24: Тестування — бригадо-днів (всього) | C24: =ROUNDUP(C5/C13,0) -> 50 | D24: бр-дн | E24: вузьке місце
B25: Монтаж — календарних днів | C25: =ROUNDUP(C5/(C12*C17),0) -> 10 | D25: дн
B26: Тестування — календарних днів | C26: =ROUNDUP(C5/(C13*C18),0) -> 17 | D26: дн
B27: Польова тривалість (з нахлестом) + буфер | C27: =MAX(C25,C26)+2 -> 19 | D27: дн | E27: планова
B28: Осіб у полі (всього) | C28: =C17*C19+C18*C20 -> 14 | D28: осіб
B30: 5. СКІЛЬКИ ПОТРІБНО ТЕСТ-БРИГАД? (тест — вузьке місце)
B31: Тест-бригад | C31: Календарних днів | D31: Робочих тижнів
B32: 1 | C32: =ROUNDUP($C$5/($C$13*B32),0) -> 50 | D32: =ROUND(C32/$C$14,1) -> 8.3 | E32: Орієнтир — 3 тест-бригади (~17 днів ≈ 3 тижні).
B33: 2 | C33: =ROUNDUP($C$5/($C$13*B33),0) -> 25 | D33: =ROUND(C33/$C$14,1) -> 4.2
B34: 3 | C34: =ROUNDUP($C$5/($C$13*B34),0) -> 17 | D34: =ROUND(C34/$C$14,1) -> 2.8
B35: 4 | C35: =ROUNDUP($C$5/($C$13*B35),0) -> 13 | D35: =ROUND(C35/$C$14,1) -> 2.2
B37: 6. ПРОГНОЗ БЮДЖЕТУ (оновлюється зі ставок у реєстрі)
B38: Разом прямі витрати | C38: ='RBS ресурсів'!$G$46 -> 0 | D38: сума розділів 1–6
B39: Резерв на непередбачене | C39: ='RBS ресурсів'!$G$47 -> 0 | D39: % від прямих
B40: РАЗОМ БЮДЖЕТ ФАЗИ 2 | C40: ='RBS ресурсів'!$G$48 -> 0 | D40: з резервом
B41: Вартість на 1 точку | C41: ='RBS ресурсів'!$G$48/C5 -> 0 | D41: бюджет / к-сть точок
B42: Польова тривалість | C42: =C27 -> 19 | D42: календарних днів

Sheet RBS ресурсів
A1: Реєстр RBS ресурсів — Greensource SGM 110 MWp · Фаза 2 · випробування 50 точок (геошурупи)
A2: Кількість — формула від «Параметрів» (можна замінити числом уручну). Ставку € вписуєте ви. Вартість і підсумки — авто.
A3: Код RBS | B3: Ресурс / стаття витрат | C3: Тип | D3: Одиниця | E3: Кількість | F3: Ставка, € | G3: Вартість, € | H3: Підказка к-сті (формула від «Параметрів»)
A4: 1 | B4: Персонал | G4: =SUM(G5:G11) -> 0
A5: 1.1 | B5: Геотехнічний експерт (випробування) | C5: Послуга | D5: люд-день | E5: =Параметри!$C$24 -> 50 | G5: =E5*F5 -> 0 | H5: тест бригадо-дні (1 експерт/бригаду)
A6: 1.2 | B6: Оператор ГАЙКа (вкручення шурупів) | C6: ЗП / бригада | D6: люд-день | E6: =Параметри!$C$23 -> 20 | G6: =E6*F6 -> 0 | H6: монтаж бригадо-дні
A7: 1.3 | B7: Оператор предрил-установки | C7: ЗП / бригада | D7: люд-день | E7: =Параметри!$C$23 -> 20 | G7: =E7*F7 -> 0 | H7: усі точки — з предрилом
A8: 1.4 | B8: Помічники монтажу | C8: ЗП / бригада | D8: люд-день | E8: =Параметри!$C$23*2 -> 40 | G8: =E8*F8 -> 0 | H8: ≈2 на бригаду
A9: 1.5 | B9: Технік/помічник випробувань | C9: ЗП / бригада | D9: люд-день | E9: =Параметри!$C$24 -> 50 | G9: =E9*F9 -> 0 | H9: 1 на тест-бригаду
A10: 1.6 | B10: Супервайзер робіт | C10: ЗП / бригада | D10: люд-день | E10: =Параметри!$C$27 -> 19 | G10: =E10*F10 -> 0 | H10: вся польова тривалість
A11: 1.7 | B11: Геодезист (розмітка точок) | C11: Послуга | D11: люд-день | E11: =ROUNDUP(Параметри!$C$5/25,0) -> 2 | G11: =E11*F11 -> 0 | H11: ≈25 точок/день
A12: 2 | B12: Обладнання (оренда) | G12: =SUM(G13:G19) -> 0
A13: 2.1 | B13: ГАЙК — гайковерт | C13: Оренда | D13: бригадо-день | E13: =Параметри!$C$23 -> 20 | G13: =E13*F13 -> 0 | H13: монтаж бригадо-дні
A14: 2.2 | B14: Предрил-установка (буріння) | C14: Оренда | D14: бригадо-день | E14: =Параметри!$C$23 -> 20 | G14: =E14*F14 -> 0 | H14: усі точки
A15: 2.3 | B15: Квадроцикл (переміщення полем) | C15: Оренда | D15: бригадо-день | E15: =Параметри!$C$23+Параметри!$C$24 -> 70 | G15: =E15*F15 -> 0 | H15: монтаж + тест
A16: 2.4 | B16: Комплект «виривання»: домкрат, насос, реакц. балка, динамометр, індикатори | C16: Оренда | D16: бригадо-день | E16: =Параметри!$C$24 -> 50 | G16: =E16*F16 -> 0 | H16: pull-out
A17: 2.5 | B17: Комплект «стиск»: домкрат, реакц. система, прогиноміри | C17: Оренда | D17: бригадо-день | E17: =Параметри!$C$24 -> 50 | G17: =E17*F17 -> 0 | H17: compression
A18: 2.6 | B18: Генератор | C18: Оренда | D18: бригадо-день | E18: =Параметри!$C$23+Параметри!$C$24 -> 70 | G18: =E18*F18 -> 0 | H18: живлення насосів/приладів
A19: 2.7 | B19: Повірка/калібрування приладів | C19: Послуга | D19: к-т | E19: =Параметри!$C$18 -> 3 | G19: =E19*F19 -> 0 | H19: на тест-бригаду
A20: 3 | B20: Матеріали та витратники | G20: =SUM(G21:G25) -> 0
A21: 3.1 | B21: Геошурупи тестові | C21: Купівля | D21: шт | E21: =Параметри!$C$5 -> 50 | G21: =E21*F21 -> 0 | H21: за к-стю точок
A22: 3.2 | B22: Реакційні анкери/палі (pull-out) | C22: Купівля | D22: шт | E22: =Параметри!$C$5*Параметри!$C$7 -> 100 | G22: =E22*F22 -> 0 | H22: анкерів на точку
A23: 3.3 | B23: Витратники предрилу (коронки/свердла) | C23: Купівля | D23: компл | E23: =Параметри!$C$5 -> 50 | G23: =E23*F23 -> 0 | H23: за к-стю точок
A24: 3.4 | B24: ГСМ (дизель / бензин A-95) | C24: Купівля | D24: л | E24: =(Параметри!$C$23+Параметри!$C$24)*Параметри!$C$8 -> 1400 | G24: =E24*F24 -> 0 | H24: бригадо-дні × добова витрата
A25: 3.5 | B25: Метизи / дрібні розхідники | C25: Купівля | D25: компл | G25: =E25*F25 -> 0 | H25: вписати вручну
A26: 4 | B26: Логістика та відрядження | G26: =SUM(G27:G32) -> 0
A27: 4.1 | B27: Мобілізація/демобілізація обладнання | C27: Послуга | D27: рейс | E27: =2 -> 2 | G27: =E27*F27 -> 0 | H27: туди-назад
A28: 4.2 | B28: Проїзд бригад (до об'єкта і назад) | C28: Відрядження | D28: осіб | E28: =Параметри!$C$28 -> 14 | G28: =E28*F28 -> 0 | H28: за положенням про відрядження
A29: 4.3 | B29: Проживання (готель) | C29: Відрядження | D29: людино-ніч | E29: =Параметри!$C$28*Параметри!$C$27 -> 266 | G29: =E29*F29 -> 0 | H29: осіб × польові дні
A30: 4.4 | B30: Добові | C30: Відрядження | D30: люд-день | E30: =Параметри!$C$28*Параметри!$C$27 -> 266 | G30: =E30*F30 -> 0 | H30: за положенням; авансовий звіт
A31: 4.5 | B31: Місцевий трансфер (готель↔майданчик) | C31: Відрядження | D31: люд-день | E31: =Параметри!$C$28*Параметри!$C$27 -> 266 | G31: =E31*F31 -> 0 | H31: щоденно
A32: 4.6 | B32: Оренда/паливо авто для переміщень | C32: Змішано | D32: л | G32: =E32*F32 -> 0 | H32: вписати вручну
A33: 5 | B33: Польові умови та побут | G33: =SUM(G34:G40) -> 0
A34: 5.1 | B34: Намет/навіс/побутівка (тінь, дощ) | C34: Оренда | D34: компл | E34: =Параметри!$C$17+Параметри!$C$18 -> 5 | G34: =E34*F34 -> 0 | H34: 1 на бригаду
A35: 5.2 | B35: Питна вода та електроліти (жара) | C35: Купівля | D35: люд-день | E35: =Параметри!$C$28*Параметри!$C$27 -> 266 | G35: =E35*F35 -> 0 | H35: осіб × польові дні
A36: 5.3 | B36: Дощовики, непромокальний одяг, гумове взуття | C36: Купівля | D36: компл | E36: =Параметри!$C$28 -> 14 | G36: =E36*F36 -> 0 | H36: на особу
A37: 5.4 | B37: Сонцезахист (креми, головні убори) | C37: Купівля | D37: компл | E37: =Параметри!$C$28 -> 14 | G37: =E37*F37 -> 0 | H37: на особу
A38: 5.5 | B38: Тенти/кейси для захисту обладнання | C38: Купівля | D38: компл | G38: =E38*F38 -> 0 | H38: вписати вручну
A39: 5.6 | B39: Біотуалет / умивальник (оренда) | C39: Оренда | D39: міс | G39: =E39*F39 -> 0 | H39: за тривалістю
A40: 5.7 | B40: Аптечка / медзабезпечення | C40: Купівля | D40: компл | E40: =Параметри!$C$17+Параметри!$C$18 -> 5 | G40: =E40*F40 -> 0 | H40: 1 на бригаду
...

Sheet Зведення
B1: Зведення бюджету по розділах RBS
B3: Розділ | C3: Вартість, € | D3: Частка
B4: 1. Персонал | C4: ='RBS ресурсів'!G4 -> 0 | D4: =IF($C$10=0,0,C4/$C$10) -> 0
B5: 2. Обладнання (оренда) | C5: ='RBS ресурсів'!G12 -> 0 | D5: =IF($C$10=0,0,C5/$C$10) -> 0
B6: 3. Матеріали та витратники | C6: ='RBS ресурсів'!G20 -> 0 | D6: =IF($C$10=0,0,C6/$C$10) -> 0
B7: 4. Логістика та відрядження | C7: ='RBS ресурсів'!G26 -> 0 | D7: =IF($C$10=0,0,C7/$C$10) -> 0
B8: 5. Польові умови та побут | C8: ='RBS ресурсів'!G33 -> 0 | D8: =IF($C$10=0,0,C8/$C$10) -> 0
B9: 6. Документи, ТБ, страхування | C9: ='RBS ресурсів'!G41 -> 0 | D9: =IF($C$10=0,0,C9/$C$10) -> 0
B10: РАЗОМ ПРЯМІ | C10: =SUM(C4:C9) -> 0

Sheet Довідники
A1: Тип статті | B1: Одиниця
A2: Оренда | B2: люд-день
A3: Купівля | B3: бригадо-день
A4: Послуга | B4: шт
A5: ЗП / бригада | B5: компл
A6: Відрядження | B6: л
A7: Змішано | B7: людино-ніч
B8: рейс
B9: к-т
B10: поліс
B11: міс
B12: —
