Workbook

Sheet Зведення
A1: Грошовий потік — звіт Pillar
A2: Дані: 30.10.2026 · без проєктів на паузі/втрачених
A4: План усього, ₴ | B4: =SUMIF('Графік надходжень'!J:J,"<>",'Графік надходжень'!F:F)
A5: Отримано (факт), ₴ | B5: =SUMIF('Графік надходжень'!J:J,"<>",'Графік надходжень'!G:G)
A6: Очікується, ₴ | B6: =B4-B5
A7: Отримано, % | B7: =IF(B4=0,0,B5/B4)
A8: Прострочені надходження, ₴ | B8: =SUMIF('Прострочені'!A:A,"<>",'Прострочені'!G:G)
A9: К-сть платежів | B9: =COUNTIF('Графік надходжень'!J2:J100000,"<>")

Sheet Графік надходжень
A1: Планова дата | B1: № проєкту | C1: Проєкт | D1: ПМ | E1: Платіж | F1: План, ₴ | G1: Факт, ₴ | H1: Різниця, ₴ | I1: Статус | J1: YM | K1: У валюті
A2: 46128 | B2: 8070 | C2: А Карпорты B2C SCP | D2: Іщук | E2: Авансовий платіж | F2: 126641 | G2: 126641 | H2: =F2-G2 | I2: отримано | J2: 2026-04
A3: 46133 | B3: 7244 | C3: В Модулекс модульна будівля Чернігів | D3: Заянчковський | E3: Авансовий платіж | F3: 77600 | G3: 77600 | H3: =F3-G3 | I3: отримано | J3: 2026-04
A4: 46139 | B4: 7536 | C4: А Ранчо “Едельвейс” AGM 171PV | D4: Іщук | E4: Авансовий платіж | F4: 244374 | G4: 244374 | H4: =F4-G4 | I4: отримано | J4: 2026-04
A5: 46147 | B5: 3456 | C5: А Підселання фундаменту | D5: Донська | E5: Авансовий платіж | F5: 421968 | G5: 421968 | H5: =F5-G5 | I5: отримано | J5: 2026-05
A6: 46149 | B6: 7536 | C6: А Ранчо “Едельвейс” AGM 171PV | D6: Іщук | E6: Другий платіж | F6: 200000 | G6: 200000 | H6: =F6-G6 | I6: отримано | J6: 2026-05
A7: 46154 | B7: 8360 | C7: Хаджет Лебедівка | D7: Донська | E7: Авансовий платіж | F7: 231000 | G7: 231000 | H7: =F7-G7 | I7: отримано | J7: 2026-05
A8: 46157 | B8: 7536 | C8: А Ранчо “Едельвейс” AGM 171PV | D8: Іщук | E8: Третій платіж | F8: 200000 | G8: 200000 | H8: =F8-G8 | I8: отримано | J8: 2026-05
A9: 46160 | B9: 8008 | C9: Модулі Григорівка | D9: Донська | E9: Авансовий платіж | F9: 430850.64 | G9: 430850.64 | H9: =F9-G9 | I9: отримано | J9: 2026-05
A10: 46161 | B10: 5870 | C10: Carport Airport Munich | D10: Хома | E10: Авансовий платіж | F10: 2525000 | G10: 2525000 | H10: =F10-G10 | I10: отримано | J10: 2026-05 | K10: €50 000
A11: 46161 | B11: 6704 | C11: SCP Taurus 236PS | D11: Хома | E11: Авансовий платіж | F11: 5050000 | G11: 5050000 | H11: =F11-G11 | I11: отримано | J11: 2026-05 | K11: €100 000
A12: 46161 | B12: 7068 | C12: А Remtec energy AGM 160 TP | D12: Александров | E12: Авансовий платіж | F12: 2416856 | G12: 2416856 | H12: =F12-G12 | I12: отримано | J12: 2026-05
A13: 46161 | B13: 8438 | C13: GS | D13: Александров | E13: Авансовий платіж | F13: 758160 | G13: 758160 | H13: =F13-G13 | I13: отримано | J13: 2026-05
A14: 46162 | B14: 7536 | C14: А Ранчо “Едельвейс” AGM 171PV | D14: Іщук | E14: Четвертий платіж | F14: 200000 | G14: 200000 | H14: =F14-G14 | I14: отримано | J14: 2026-05
A15: 46164 | B15: 8238 | C15: А UTEM SOLAR SCP Taurus 190PV | D15: Іщук | E15: Авансовий платіж | F15: 2050102 | G15: 2050102 | H15: =F15-G15 | I15: отримано | J15: 2026-05 | K15: $45 700
A16: 46166 | B16: 7536 | C16: А Ранчо “Едельвейс” AGM 171PV | D16: Іщук | E16: П'ятий платіж | F16: 67972.8 | G16: 67972.8 | H16: =F16-G16 | I16: отримано | J16: 2026-05
A17: 46167 | B17: 7508 | C17: 8602 Євген Весільна тераса Подорожнє | D17: Заянчковський | E17: Авансовий платіж | F17: 1245999.9 | G17: 1245999.9 | H17: =F17-G17 | I17: отримано | J17: 2026-05
A18: 46168 | B18: 7508 | C18: 8602 Євген Весільна тераса Подорожнє | D18: Заянчковський | E18: Другий платіж | F18: 751000.06 | G18: 751000.06 | H18: =F18-G18 | I18: отримано | J18: 2026-05
A19: 46168 | B19: 8140 | C19: В Газинвестпроект фундамент Киев | D19: Заянчковський | E19: Авансовий платіж | F19: 150000 | G19: 150000 | H19: =F19-G19 | I19: отримано | J19: 2026-05
A20: 46169 | B20: 6842 | C20: 2 | D20: Александров | E20: Авансовий платіж | F20: 3308968 | G20: 3308968 | H20: =F20-G20 | I20: отримано | J20: 2026-05
A21: 46169 | B21: 7960 | C21: Сірокко Sirocco вітрова ел ст Львів | D21: Іщук | E21: Авансовий платіж | F21: 99610.8 | G21: 99610.8 | H21: =F21-G21 | I21: отримано | J21: 2026-05
A22: 46169 | B22: 8454 | C22: Олександр каркасний Верховина | D22: Донська | E22: Авансовий платіж | F22: 103606.2 | G22: 103606.2 | H22: =F22-G22 | I22: отримано | J22: 2026-05
A23: 46170 | B23: 8188 | C23: Фундамент Ужгород Стефанія | D23: Іщук | E23: Авансовий платіж | F23: 206200 | G23: 206200 | H23: =F23-G23 | I23: отримано | J23: 2026-05
A24: 46170 | B24: 8454 | C24: Олександр каркасний Верховина | D24: Донська | E24: Другий платіж | F24: 69666 | G24: 69666 | H24: =F24-G24 | I24: отримано | J24: 2026-05
A25: 46170 | B25: 8544 | C25: Isolar фланець Хмельницький | D25: Донська | E25: Авансовий платіж | F25: 261990 | G25: 261990 | H25: =F25-G25 | I25: отримано | J25: 2026-05
A26: 46175 | B26: 5682 | C26: А Сцена Корчин | D26: Іщук | E26: Авансовий платіж | F26: 87150 | G26: 87150 | H26: =F26-G26 | I26: отримано | J26: 2026-06
A27: 46175 | B27: 8185 | C27: Фундамент Hytte House Development Славське | D27: Донська | E27: Авансовий платіж | F27: 168024 | G27: 168024 | H27: =F27-G27 | I27: отримано | J27: 2026-06
... A38: 46197 | B38: 8360 | C38: Хаджет Лебедівка | D38: Донська | E38: Третій платіж | F38: 95968.3 | G38: 95968.3 | H38: =F38-G38 | I38: отримано | J38: 2026-06
A39: 46202 | B39: 6704 | C39: SCP Taurus 236PS | D39: Хома | E39: Другий платіж | F39: 1818000 | G39: 1818000 | H39: =F39-G39 | I39: отримано | J39: 2026-06 | K39: €36 000
A40: 46204 | B40: 4766 | C40: ALTECO Carport Model Taurus 280кВт | D40: Заянчковський | E40: Авансовий платіж | F40: 20000 | G40: 20000 | H40: =F40-G40 | I40: отримано | J40: 2026-07
A41: 46209 | B41: 8878 | C41: А ТОВ КОМПАНІЯ ВОЛЬТ СЕРВІС ГРУП | D41: Заянчковський | E41: Авансовий платіж | F41: 410320 | G41: 410320 | H41: =F41-G41 | I41: отримано | J41: 2026-07
A42: 46210 | B42: 8008 | C42: Модулі Григорівка | D42: Донська | E42: Третій платіж | F42: 178088.4 | G42: 178088.4 | H42: =F42-G42 | I42: отримано | J42: 2026-07
A43: 46213 | B43: 8454 | C43: Олександр каркасний Верховина | D43: Донська | E43: Третій платіж | F43: 69666 | G43: 69666 | H43: =F43-G43 | I43: отримано | J43: 2026-07
A44: 46216 | B44: 8496 | C44: А Greensource SGM 110MWp | D44: Іщук | E44: Авансовий платіж | F44: 444400 | G44: 444400 | H44: =F44-G44 | I44: отримано | J44: 2026-07 | K44: €8 800
A45: 46216 | B45: 8898 | C45: Григорівка №3 | D45: Донська | E45: Авансовий платіж | F45: 290403.65 | G45: 290403.65 | H45: =F45-G45 | I45: отримано | J45: 2026-07
A46: 46217 | B46: 4766 | C46: ALTECO Carport Model Taurus 280кВт | D46: Заянчковський | E46: Другий платіж | F46: 100000 | G46: 100000 | H46: =F46-G46 | I46: отримано | J46: 2026-07
A47: 46217 | B47: 8185 | C47: Фундамент Hytte House Development Славське | D47: Донська | E47: Другий платіж | F47: 63313.4 | G47: 63313.4 | H47: =F47-G47 | I47: отримано | J47: 2026-07
A48: 46217 | B48: 8185 | C48: Фундамент Hytte House Development Славське | D48: Донська | E48: Третій платіж | F48: 63313.4 | G48: 63313.4 | H48: =F48-G48 | I48: отримано | J48: 2026-07
A49: 46219 | B49: 6352 | C49: АБМК SCP Blade 8PS | D49: Донська | E49: Авансовий платіж | F49: 80000.04 | G49: 80000.04 | H49: =F49-G49 | I49: отримано | J49: 2026-07
A50: 46219 | B50: 7002 | C50: Фора SCP Млиново | D50: Донська | E50: Авансовий платіж | F50: 126896.64 | G50: 126896.64 | H50: =F50-G50 | I50: отримано | J50: 2026-07
...

Sheet По місяцях
A1: Місяць | B1: План, ₴ | C1: Факт, ₴ | D1: Різниця, ₴ | E1: % отримано
A2: кві 2026 | B2: =SUMIF('Графік надходжень'!J:J,"2026-04",'Графік надходжень'!F:F) | C2: =SUMIF('Графік надходжень'!J:J,"2026-04",'Графік надходжень'!G:G) | D2: =B2-C2 | E2: =IF(B2=0,0,C2/B2)
A3: тра 2026 | B3: =SUMIF('Графік надходжень'!J:J,"2026-05",'Графік надходжень'!F:F) | C3: =SUMIF('Графік надходжень'!J:J,"2026-05",'Графік надходжень'!G:G) | D3: =B3-C3 | E3: =IF(B3=0,0,C3/B3)
A4: чер 2026 | B4: =SUMIF('Графік надходжень'!J:J,"2026-06",'Графік надходжень'!F:F) | C4: =SUMIF('Графік надходжень'!J:J,"2026-06",'Графік надходжень'!G:G) | D4: =B4-C4 | E4: =IF(B4=0,0,C4/B4)
A5: лип 2026 | B5: =SUMIF('Графік надходжень'!J:J,"2026-07",'Графік надходжень'!F:F) | C5: =SUMIF('Графік надходжень'!J:J,"2026-07",'Графік надходжень'!G:G) | D5: =B5-C5 | E5: =IF(B5=0,0,C5/B5)
A6: сер 2026 | B6: =SUMIF('Графік надходжень'!J:J,"2026-08",'Графік надходжень'!F:F) | C6: =SUMIF('Графік надходжень'!J:J,"2026-08",'Графік надходжень'!G:G) | D6: =B6-C6 | E6: =IF(B6=0,0,C6/B6)
A7: вер 2026 | B7: =SUMIF('Графік надходжень'!J:J,"2026-09",'Графік надходжень'!F:F) | C7: =SUMIF('Графік надходжень'!J:J,"2026-09",'Графік надходжень'!G:G) | D7: =B7-C7 | E7: =IF(B7=0,0,C7/B7)
A8: жов 2026 | B8: =SUMIF('Графік надходжень'!J:J,"2026-10",'Графік надходжень'!F:F) | C8: =SUMIF('Графік надходжень'!J:J,"2026-10",'Графік надходжень'!G:G) | D8: =B8-C8 | E8: =IF(B8=0,0,C8/B8)
A9: лис 2026 | B9: =SUMIF('Графік надходжень'!J:J,"2026-11",'Графік надходжень'!F:F) | C9: =SUMIF('Графік надходжень'!J:J,"2026-11",'Графік надходжень'!G:G) | D9: =B9-C9 | E9: =IF(B9=0,0,C9/B9)
A10: Разом | B10: =SUM(B2:B9) | C10: =SUM(C2:C9) | D10: =SUM(D2:D9) | E10: =IF(B10=0,0,C10/B10)

Sheet Прострочені
A1: Планова дата | B1: № проєкту | C1: Проєкт | D1: Платіж | E1: План, ₴ | F1: Факт, ₴ | G1: Борг, ₴
A2: 46325 | B2: 5910 | C2: SGM Brdovec, Хорватия | D2: Третій платіж | E2: 2812547 | F2: 1341330.5 | G2: =E2-F2
A3: 46325 | B3: 5910 | C3: SGM Brdovec, Хорватия | D3: Другий платіж 60% | E3: 16876140 | F3: 15646466 | G3: =E3-F3
A4: 46325 | B4: 4766 | C4: ALTECO Carport Model Taurus 280кВт | D4: П'ятий платіж | E4: 1263447.4 | F4: 1050000 | G4: =E4-F4
A5: 46325 | B5: 7244 | C5: В Модулекс модульна будівля Чернігів | D5: П'ятий платіж | E5: 132708.6 | F5: 0 | G5: =E5-F5
A6: 46260 | B6: 6406 | C6: Максим Яловий Чинадієво | D6: Другий платіж | E6: 218602 | F6: 170788 | G6: =E6-F6
D7: Разом | E7: =SUM(E2:E6) | F7: =SUM(F2:F6) | G7: =SUM(G2:G6)
